//// [tests/cases/conformance/statements/tryStatements/invalidTryStatements.ts] ////

=== invalidTryStatements.ts ===
function fn() {
>fn : () => void
>   : ^^^^^^^^^^

    catch(x) { } // error missing try
>x : any
>  : ^^^

    finally { } // potential error; can be absorbed by the 'catch'

    try { }; // error missing finally
}

function fn2() {
>fn2 : () => void
>    : ^^^^^^^^^^

    finally { } // error missing try
    catch (x) { } // error missing try
>x : any
>  : ^^^
    
    try { } finally { } // statement is here, so the 'catch' clause above doesn't absorb errors from the 'finally' clause below

    finally { } // error missing try
    
    catch (x) { } // error missing try
>x : any
>  : ^^^

    try { } catch () { } // error missing catch binding
> : any
> : ^^^
}
